[03/04/2022 14:56:26.212]	 ERROR 	[server.log_exception:1891]	 Exception on /health [GET]
Traceback (most recent call last):
  File "C:\Users\soren\anaconda3\lib\site-packages\flask\app.py", line 2447, in wsgi_app
    response = self.full_dispatch_request()
  File "C:\Users\soren\anaconda3\lib\site-packages\flask\app.py", line 1952, in full_dispatch_request
    rv = self.handle_user_exception(e)
  File "C:\Users\soren\anaconda3\lib\site-packages\flask\app.py", line 1821, in handle_user_exception
    reraise(exc_type, exc_value, tb)
  File "C:\Users\soren\anaconda3\lib\site-packages\flask\_compat.py", line 39, in reraise
    raise value
  File "C:\Users\soren\anaconda3\lib\site-packages\flask\app.py", line 1950, in full_dispatch_request
    rv = self.dispatch_request()
  File "C:\Users\soren\anaconda3\lib\site-packages\flask\app.py", line 1936, in dispatch_request
    return self.view_functions[rule.endpoint](**req.view_args)
  File "C:\Users\soren\Documents\GitHub\DevOps_AD4_Capacidades_despliegue\endpoints\public.py", line 93, in health_check
    stat = subprocess.call(["systemctl", "is-active", "--quiet", "ssh"])
  File "C:\Users\soren\anaconda3\lib\subprocess.py", line 349, in call
    with Popen(*popenargs, **kwargs) as p:
  File "C:\Users\soren\anaconda3\lib\subprocess.py", line 951, in __init__
    self._execute_child(args, executable, preexec_fn, close_fds,
  File "C:\Users\soren\anaconda3\lib\subprocess.py", line 1420, in _execute_child
    hp, ht, pid, tid = _winapi.CreateProcess(executable, args,
FileNotFoundError: [WinError 2] El sistema no puede encontrar el archivo especificado
[03/04/2022 14:56:34.2]	 ERROR 	[server.log_exception:1891]	 Exception on /health [GET]
Traceback (most recent call last):
  File "C:\Users\soren\anaconda3\lib\site-packages\flask\app.py", line 2447, in wsgi_app
    response = self.full_dispatch_request()
  File "C:\Users\soren\anaconda3\lib\site-packages\flask\app.py", line 1952, in full_dispatch_request
    rv = self.handle_user_exception(e)
  File "C:\Users\soren\anaconda3\lib\site-packages\flask\app.py", line 1821, in handle_user_exception
    reraise(exc_type, exc_value, tb)
  File "C:\Users\soren\anaconda3\lib\site-packages\flask\_compat.py", line 39, in reraise
    raise value
  File "C:\Users\soren\anaconda3\lib\site-packages\flask\app.py", line 1950, in full_dispatch_request
    rv = self.dispatch_request()
  File "C:\Users\soren\anaconda3\lib\site-packages\flask\app.py", line 1936, in dispatch_request
    return self.view_functions[rule.endpoint](**req.view_args)
  File "C:\Users\soren\Documents\GitHub\DevOps_AD4_Capacidades_despliegue\endpoints\public.py", line 93, in health_check
    stat = subprocess.call(["systemctl", "is-active", "--quiet", "ssh"])
  File "C:\Users\soren\anaconda3\lib\subprocess.py", line 349, in call
    with Popen(*popenargs, **kwargs) as p:
  File "C:\Users\soren\anaconda3\lib\subprocess.py", line 951, in __init__
    self._execute_child(args, executable, preexec_fn, close_fds,
  File "C:\Users\soren\anaconda3\lib\subprocess.py", line 1420, in _execute_child
    hp, ht, pid, tid = _winapi.CreateProcess(executable, args,
FileNotFoundError: [WinError 2] El sistema no puede encontrar el archivo especificado
[03/04/2022 14:56:39.77]	 ERROR 	[server.log_exception:1891]	 Exception on /ready [GET]
Traceback (most recent call last):
  File "C:\Users\soren\anaconda3\lib\site-packages\flask\app.py", line 2447, in wsgi_app
    response = self.full_dispatch_request()
  File "C:\Users\soren\anaconda3\lib\site-packages\flask\app.py", line 1952, in full_dispatch_request
    rv = self.handle_user_exception(e)
  File "C:\Users\soren\anaconda3\lib\site-packages\flask\app.py", line 1821, in handle_user_exception
    reraise(exc_type, exc_value, tb)
  File "C:\Users\soren\anaconda3\lib\site-packages\flask\_compat.py", line 39, in reraise
    raise value
  File "C:\Users\soren\anaconda3\lib\site-packages\flask\app.py", line 1950, in full_dispatch_request
    rv = self.dispatch_request()
  File "C:\Users\soren\anaconda3\lib\site-packages\flask\app.py", line 1936, in dispatch_request
    return self.view_functions[rule.endpoint](**req.view_args)
  File "C:\Users\soren\Documents\GitHub\DevOps_AD4_Capacidades_despliegue\endpoints\public.py", line 81, in ready_check
    if db.connect():
AttributeError: 'SQLAlchemy' object has no attribute 'connect'
[03/04/2022 14:57:22.759]	 ERROR 	[server.log_exception:1891]	 Exception on /health [GET]
Traceback (most recent call last):
  File "C:\Users\soren\anaconda3\lib\site-packages\flask\app.py", line 2447, in wsgi_app
    response = self.full_dispatch_request()
  File "C:\Users\soren\anaconda3\lib\site-packages\flask\app.py", line 1952, in full_dispatch_request
    rv = self.handle_user_exception(e)
  File "C:\Users\soren\anaconda3\lib\site-packages\flask\app.py", line 1821, in handle_user_exception
    reraise(exc_type, exc_value, tb)
  File "C:\Users\soren\anaconda3\lib\site-packages\flask\_compat.py", line 39, in reraise
    raise value
  File "C:\Users\soren\anaconda3\lib\site-packages\flask\app.py", line 1950, in full_dispatch_request
    rv = self.dispatch_request()
  File "C:\Users\soren\anaconda3\lib\site-packages\flask\app.py", line 1936, in dispatch_request
    return self.view_functions[rule.endpoint](**req.view_args)
  File "C:\Users\soren\Documents\GitHub\DevOps_AD4_Capacidades_despliegue\endpoints\public.py", line 93, in health_check
    stat = subprocess.call(["systemctl", "is-active", "--quiet", "ssh"])
  File "C:\Users\soren\anaconda3\lib\subprocess.py", line 349, in call
    with Popen(*popenargs, **kwargs) as p:
  File "C:\Users\soren\anaconda3\lib\subprocess.py", line 951, in __init__
    self._execute_child(args, executable, preexec_fn, close_fds,
  File "C:\Users\soren\anaconda3\lib\subprocess.py", line 1420, in _execute_child
    hp, ht, pid, tid = _winapi.CreateProcess(executable, args,
FileNotFoundError: [WinError 2] El sistema no puede encontrar el archivo especificado
[03/04/2022 16:38:00.728]	 ERROR 	[server.log_exception:1891]	 Exception on /health [GET]
Traceback (most recent call last):
  File "C:\Users\soren\anaconda3\lib\site-packages\flask\app.py", line 2447, in wsgi_app
    response = self.full_dispatch_request()
  File "C:\Users\soren\anaconda3\lib\site-packages\flask\app.py", line 1952, in full_dispatch_request
    rv = self.handle_user_exception(e)
  File "C:\Users\soren\anaconda3\lib\site-packages\flask\app.py", line 1821, in handle_user_exception
    reraise(exc_type, exc_value, tb)
  File "C:\Users\soren\anaconda3\lib\site-packages\flask\_compat.py", line 39, in reraise
    raise value
  File "C:\Users\soren\anaconda3\lib\site-packages\flask\app.py", line 1950, in full_dispatch_request
    rv = self.dispatch_request()
  File "C:\Users\soren\anaconda3\lib\site-packages\flask\app.py", line 1936, in dispatch_request
    return self.view_functions[rule.endpoint](**req.view_args)
  File "C:\Users\soren\Documents\GitHub\DevOps_AD4_Capacidades_despliegue\endpoints\public.py", line 94, in health_check
    stat = subprocess.call(["systemctl", "is-active", "--quiet", "ssh"])
  File "C:\Users\soren\anaconda3\lib\subprocess.py", line 349, in call
    with Popen(*popenargs, **kwargs) as p:
  File "C:\Users\soren\anaconda3\lib\subprocess.py", line 951, in __init__
    self._execute_child(args, executable, preexec_fn, close_fds,
  File "C:\Users\soren\anaconda3\lib\subprocess.py", line 1420, in _execute_child
    hp, ht, pid, tid = _winapi.CreateProcess(executable, args,
FileNotFoundError: [WinError 2] El sistema no puede encontrar el archivo especificado
[03/04/2022 16:38:11.410]	 ERROR 	[server.log_exception:1891]	 Exception on /health [GET]
Traceback (most recent call last):
  File "C:\Users\soren\anaconda3\lib\site-packages\flask\app.py", line 2447, in wsgi_app
    response = self.full_dispatch_request()
  File "C:\Users\soren\anaconda3\lib\site-packages\flask\app.py", line 1952, in full_dispatch_request
    rv = self.handle_user_exception(e)
  File "C:\Users\soren\anaconda3\lib\site-packages\flask\app.py", line 1821, in handle_user_exception
    reraise(exc_type, exc_value, tb)
  File "C:\Users\soren\anaconda3\lib\site-packages\flask\_compat.py", line 39, in reraise
    raise value
  File "C:\Users\soren\anaconda3\lib\site-packages\flask\app.py", line 1950, in full_dispatch_request
    rv = self.dispatch_request()
  File "C:\Users\soren\anaconda3\lib\site-packages\flask\app.py", line 1936, in dispatch_request
    return self.view_functions[rule.endpoint](**req.view_args)
  File "C:\Users\soren\Documents\GitHub\DevOps_AD4_Capacidades_despliegue\endpoints\public.py", line 94, in health_check
    stat = subprocess.call(["systemctl", "is-active", "--quiet", "ssh"])
  File "C:\Users\soren\anaconda3\lib\subprocess.py", line 349, in call
    with Popen(*popenargs, **kwargs) as p:
  File "C:\Users\soren\anaconda3\lib\subprocess.py", line 951, in __init__
    self._execute_child(args, executable, preexec_fn, close_fds,
  File "C:\Users\soren\anaconda3\lib\subprocess.py", line 1420, in _execute_child
    hp, ht, pid, tid = _winapi.CreateProcess(executable, args,
FileNotFoundError: [WinError 2] El sistema no puede encontrar el archivo especificado
[03/04/2022 17:05:58.829]	 ERROR 	[server.log_exception:1891]	 Exception on /ready [GET]
Traceback (most recent call last):
  File "C:\Users\soren\anaconda3\lib\site-packages\flask\app.py", line 2447, in wsgi_app
    response = self.full_dispatch_request()
  File "C:\Users\soren\anaconda3\lib\site-packages\flask\app.py", line 1952, in full_dispatch_request
    rv = self.handle_user_exception(e)
  File "C:\Users\soren\anaconda3\lib\site-packages\flask\app.py", line 1821, in handle_user_exception
    reraise(exc_type, exc_value, tb)
  File "C:\Users\soren\anaconda3\lib\site-packages\flask\_compat.py", line 39, in reraise
    raise value
  File "C:\Users\soren\anaconda3\lib\site-packages\flask\app.py", line 1950, in full_dispatch_request
    rv = self.dispatch_request()
  File "C:\Users\soren\anaconda3\lib\site-packages\flask\app.py", line 1936, in dispatch_request
    return self.view_functions[rule.endpoint](**req.view_args)
  File "C:\Users\soren\Documents\GitHub\DevOps_AD4_Capacidades_despliegue\endpoints\public.py", line 82, in ready_check
    if db.connect():
AttributeError: 'SQLAlchemy' object has no attribute 'connect'
